[2023-10-11T04:38:16.605+0000] {taskinstance.py:1157} INFO - Dependencies all met for dep_context=non-requeueable deps ti=<TaskInstance: docker.virtualenv_python manual__2023-10-11T04:38:14.587987+00:00 [queued]>
[2023-10-11T04:38:16.609+0000] {taskinstance.py:1157} INFO - Dependencies all met for dep_context=requeueable deps ti=<TaskInstance: docker.virtualenv_python manual__2023-10-11T04:38:14.587987+00:00 [queued]>
[2023-10-11T04:38:16.609+0000] {taskinstance.py:1359} INFO - Starting attempt 1 of 1
[2023-10-11T04:38:16.615+0000] {taskinstance.py:1380} INFO - Executing <Task(_PythonVirtualenvDecoratedOperator): virtualenv_python> on 2023-10-11 04:38:14.587987+00:00
[2023-10-11T04:38:16.621+0000] {standard_task_runner.py:57} INFO - Started process 327 to run task
[2023-10-11T04:38:16.623+0000] {standard_task_runner.py:84} INFO - Running: ['***', 'tasks', 'run', 'docker', 'virtualenv_python', 'manual__2023-10-11T04:38:14.587987+00:00', '--job-id', '1408', '--raw', '--subdir', 'DAGS_FOLDER/docker.py', '--cfg-path', '/tmp/tmpc5aga4h2']
[2023-10-11T04:38:16.623+0000] {standard_task_runner.py:85} INFO - Job 1408: Subtask virtualenv_python
[2023-10-11T04:38:16.650+0000] {task_command.py:415} INFO - Running <TaskInstance: docker.virtualenv_python manual__2023-10-11T04:38:14.587987+00:00 [running]> on host 1e16ce4c9e98
[2023-10-11T04:38:16.687+0000] {taskinstance.py:1660} INFO - Exporting env vars: AIRFLOW_CTX_DAG_OWNER='***' AIRFLOW_CTX_DAG_ID='docker' AIRFLOW_CTX_TASK_ID='virtualenv_python' AIRFLOW_CTX_EXECUTION_DATE='2023-10-11T04:38:14.587987+00:00' AIRFLOW_CTX_TRY_NUMBER='1' AIRFLOW_CTX_DAG_RUN_ID='manual__2023-10-11T04:38:14.587987+00:00'
[2023-10-11T04:38:16.689+0000] {process_utils.py:182} INFO - Executing cmd: /usr/local/bin/python -m virtualenv /tmp/venvs4r1sypf
[2023-10-11T04:38:16.700+0000] {process_utils.py:186} INFO - Output:
[2023-10-11T04:38:17.492+0000] {process_utils.py:190} INFO - created virtual environment CPython3.8.18.final.0-64 in 279ms
[2023-10-11T04:38:17.492+0000] {process_utils.py:190} INFO -   creator CPython3Posix(dest=/tmp/venvs4r1sypf, clear=False, no_vcs_ignore=False, global=False)
[2023-10-11T04:38:17.493+0000] {process_utils.py:190} INFO -   seeder FromAppData(download=False, pip=bundle, setuptools=bundle, wheel=bundle, via=copy, app_data_dir=/tmp/tmpfn486p7w)
[2023-10-11T04:38:17.493+0000] {process_utils.py:190} INFO -     added seed packages: pip==23.2, setuptools==68.0.0, wheel==0.40.0
[2023-10-11T04:38:17.493+0000] {process_utils.py:190} INFO -   activators BashActivator,CShellActivator,FishActivator,NushellActivator,PowerShellActivator,PythonActivator
[2023-10-11T04:38:17.518+0000] {process_utils.py:182} INFO - Executing cmd: /tmp/venvs4r1sypf/bin/pip install -r /tmp/venvs4r1sypf/requirements.txt
[2023-10-11T04:38:17.530+0000] {process_utils.py:186} INFO - Output:
[2023-10-11T04:38:18.333+0000] {process_utils.py:190} INFO - WARNING: The directory '/home/***/.cache/pip' or its parent directory is not owned or is not writable by the current user. The cache has been disabled. Check the permissions and owner of that directory. If executing pip with sudo, you should use sudo's -H flag.
[2023-10-11T04:38:18.561+0000] {process_utils.py:190} INFO - Collecting lightgbm==4.1.0 (from -r /tmp/venvs4r1sypf/requirements.txt (line 1))
[2023-10-11T04:38:18.562+0000] {process_utils.py:190} INFO -   Obtaining dependency information for lightgbm==4.1.0 from https://files.pythonhosted.org/packages/b8/9d/1ce80cee7c5ef60f2fcc7e9fa97f29f7a8de3dc5a08922b3b2f1e9106481/lightgbm-4.1.0-py3-none-manylinux_2_28_x86_64.whl.metadata
[2023-10-11T04:38:18.705+0000] {process_utils.py:190} INFO -   Downloading lightgbm-4.1.0-py3-none-manylinux_2_28_x86_64.whl.metadata (19 kB)
[2023-10-11T04:38:18.990+0000] {process_utils.py:190} INFO - ERROR: Ignored the following versions that require a different python version: 2.1.0 Requires-Python >=3.9; 2.1.0rc0 Requires-Python >=3.9; 2.1.1 Requires-Python >=3.9
[2023-10-11T04:38:18.991+0000] {process_utils.py:190} INFO - ERROR: Could not find a version that satisfies the requirement pandas==2.1.1 (from versions: 0.1, 0.2, 0.3.0, 0.4.0, 0.4.1, 0.4.2, 0.4.3, 0.5.0, 0.6.0, 0.6.1, 0.7.0, 0.7.1, 0.7.2, 0.7.3, 0.8.0, 0.8.1, 0.9.0, 0.9.1, 0.10.0, 0.10.1, 0.11.0, 0.12.0, 0.13.0, 0.13.1, 0.14.0, 0.14.1, 0.15.0, 0.15.1, 0.15.2, 0.16.0, 0.16.1, 0.16.2, 0.17.0, 0.17.1, 0.18.0, 0.18.1, 0.19.0, 0.19.1, 0.19.2, 0.20.0, 0.20.1, 0.20.2, 0.20.3, 0.21.0, 0.21.1, 0.22.0, 0.23.0, 0.23.1, 0.23.2, 0.23.3, 0.23.4, 0.24.0, 0.24.1, 0.24.2, 0.25.0, 0.25.1, 0.25.2, 0.25.3, 1.0.0, 1.0.1, 1.0.2, 1.0.3, 1.0.4, 1.0.5, 1.1.0, 1.1.1, 1.1.2, 1.1.3, 1.1.4, 1.1.5, 1.2.0, 1.2.1, 1.2.2, 1.2.3, 1.2.4, 1.2.5, 1.3.0, 1.3.1, 1.3.2, 1.3.3, 1.3.4, 1.3.5, 1.4.0rc0, 1.4.0, 1.4.1, 1.4.2, 1.4.3, 1.4.4, 1.5.0rc0, 1.5.0, 1.5.1, 1.5.2, 1.5.3, 2.0.0rc0, 2.0.0rc1, 2.0.0, 2.0.1, 2.0.2, 2.0.3)
[2023-10-11T04:38:18.991+0000] {process_utils.py:190} INFO - ERROR: No matching distribution found for pandas==2.1.1
[2023-10-11T04:38:19.156+0000] {process_utils.py:190} INFO - 
[2023-10-11T04:38:19.156+0000] {process_utils.py:190} INFO - [notice] A new release of pip is available: 23.2 -> 23.2.1
[2023-10-11T04:38:19.156+0000] {process_utils.py:190} INFO - [notice] To update, run: python -m pip install --upgrade pip
[2023-10-11T04:38:19.240+0000] {taskinstance.py:1935} ERROR - Task failed with exception
Traceback (most recent call last):
  File "/home/airflow/.local/lib/python3.8/site-packages/airflow/decorators/base.py", line 221, in execute
    return_value = super().execute(context)
  File "/home/airflow/.local/lib/python3.8/site-packages/airflow/operators/python.py", line 395, in execute
    return super().execute(context=serializable_context)
  File "/home/airflow/.local/lib/python3.8/site-packages/airflow/operators/python.py", line 192, in execute
    return_value = self.execute_callable()
  File "/home/airflow/.local/lib/python3.8/site-packages/airflow/operators/python.py", line 594, in execute_callable
    prepare_virtualenv(
  File "/home/airflow/.local/lib/python3.8/site-packages/airflow/utils/python_virtualenv.py", line 100, in prepare_virtualenv
    execute_in_subprocess(pip_cmd)
  File "/home/airflow/.local/lib/python3.8/site-packages/airflow/utils/process_utils.py", line 171, in execute_in_subprocess
    execute_in_subprocess_with_kwargs(cmd, cwd=cwd)
  File "/home/airflow/.local/lib/python3.8/site-packages/airflow/utils/process_utils.py", line 194, in execute_in_subprocess_with_kwargs
    raise subprocess.CalledProcessError(exit_code, cmd)
subprocess.CalledProcessError: Command '['/tmp/venvs4r1sypf/bin/pip', 'install', '-r', '/tmp/venvs4r1sypf/requirements.txt']' returned non-zero exit status 1.
[2023-10-11T04:38:19.247+0000] {taskinstance.py:1398} INFO - Marking task as FAILED. dag_id=docker, task_id=virtualenv_python, execution_date=20231011T043814, start_date=20231011T043816, end_date=20231011T043819
[2023-10-11T04:38:19.256+0000] {standard_task_runner.py:104} ERROR - Failed to execute job 1408 for task virtualenv_python (Command '['/tmp/venvs4r1sypf/bin/pip', 'install', '-r', '/tmp/venvs4r1sypf/requirements.txt']' returned non-zero exit status 1.; 327)
[2023-10-11T04:38:19.279+0000] {local_task_job_runner.py:228} INFO - Task exited with return code 1
[2023-10-11T04:38:19.292+0000] {taskinstance.py:2776} INFO - 0 downstream tasks scheduled from follow-on schedule check
