[2023-11-12T15:18:07.745+0000] {taskinstance.py:1157} INFO - Dependencies all met for dep_context=non-requeueable deps ti=<TaskInstance: docker_cb.train_task manual__2023-11-12T15:18:06.506377+00:00 [queued]>
[2023-11-12T15:18:07.755+0000] {taskinstance.py:1157} INFO - Dependencies all met for dep_context=requeueable deps ti=<TaskInstance: docker_cb.train_task manual__2023-11-12T15:18:06.506377+00:00 [queued]>
[2023-11-12T15:18:07.755+0000] {taskinstance.py:1359} INFO - Starting attempt 1 of 1
[2023-11-12T15:18:07.767+0000] {taskinstance.py:1380} INFO - Executing <Task(DockerOperator): train_task> on 2023-11-12 15:18:06.506377+00:00
[2023-11-12T15:18:07.773+0000] {standard_task_runner.py:57} INFO - Started process 73 to run task
[2023-11-12T15:18:07.777+0000] {standard_task_runner.py:84} INFO - Running: ['***', 'tasks', 'run', 'docker_cb', 'train_task', 'manual__2023-11-12T15:18:06.506377+00:00', '--job-id', '3', '--raw', '--subdir', 'DAGS_FOLDER/catboost/docker.py', '--cfg-path', '/tmp/tmpcrh7l7to']
[2023-11-12T15:18:07.778+0000] {standard_task_runner.py:85} INFO - Job 3: Subtask train_task
[2023-11-12T15:18:07.824+0000] {task_command.py:415} INFO - Running <TaskInstance: docker_cb.train_task manual__2023-11-12T15:18:06.506377+00:00 [running]> on host 1905040b710e
[2023-11-12T15:18:07.899+0000] {taskinstance.py:1660} INFO - Exporting env vars: AIRFLOW_CTX_DAG_OWNER='***' AIRFLOW_CTX_DAG_ID='docker_cb' AIRFLOW_CTX_TASK_ID='train_task' AIRFLOW_CTX_EXECUTION_DATE='2023-11-12T15:18:06.506377+00:00' AIRFLOW_CTX_TRY_NUMBER='1' AIRFLOW_CTX_DAG_RUN_ID='manual__2023-11-12T15:18:06.506377+00:00'
[2023-11-12T15:18:07.932+0000] {docker.py:337} INFO - Starting docker container from image dunghoang99/***-cb-stage:0.0.1
[2023-11-12T15:18:07.941+0000] {docker.py:345} WARNING - Using remote engine or docker-in-docker and mounting temporary volume from host is not supported. Falling back to `mount_tmp_dir=False` mode. You can set `mount_tmp_dir` parameter to False to disable mounting and remove the warning
[2023-11-12T15:18:09.064+0000] {docker.py:406} INFO - Traceback (most recent call last):
  File "/training/code/train.py", line 39, in <module>
[2023-11-12T15:18:09.065+0000] {docker.py:406} INFO - df = pd.read_csv(file_path)
  File "/usr/local/lib/python3.9/site-packages/pandas/io/parsers/readers.py", line 912, in read_csv
[2023-11-12T15:18:09.065+0000] {docker.py:406} INFO - return _read(filepath_or_buffer, kwds)
  File "/usr/local/lib/python3.9/site-packages/pandas/io/parsers/readers.py", line 577, in _read
[2023-11-12T15:18:09.066+0000] {docker.py:406} INFO - parser = TextFileReader(filepath_or_buffer, **kwds)
  File "/usr/local/lib/python3.9/site-packages/pandas/io/parsers/readers.py", line 1407, in __init__
[2023-11-12T15:18:09.067+0000] {docker.py:406} INFO - self._engine = self._make_engine(f, self.engine)
[2023-11-12T15:18:09.068+0000] {docker.py:406} INFO - File "/usr/local/lib/python3.9/site-packages/pandas/io/parsers/readers.py", line 1661, in _make_engine
[2023-11-12T15:18:09.069+0000] {docker.py:406} INFO - self.handles = get_handle(
[2023-11-12T15:18:09.070+0000] {docker.py:406} INFO - File "/usr/local/lib/python3.9/site-packages/pandas/io/common.py", line 859, in get_handle
[2023-11-12T15:18:09.071+0000] {docker.py:406} INFO - handle = open(
[2023-11-12T15:18:09.072+0000] {docker.py:406} INFO - IsADirectoryError: [Errno 21] Is a directory: '/training/data/diabetes'
[2023-11-12T15:18:09.383+0000] {taskinstance.py:1935} ERROR - Task failed with exception
Traceback (most recent call last):
  File "/home/airflow/.local/lib/python3.8/site-packages/docker/api/client.py", line 268, in _raise_for_status
    response.raise_for_status()
  File "/home/airflow/.local/lib/python3.8/site-packages/requests/models.py", line 1021, in raise_for_status
    raise HTTPError(http_error_msg, response=self)
requests.exceptions.HTTPError: 400 Client Error: Bad Request for url: http://docker-proxy:2375/v1.43/containers/create?name=***-cb-stage

The above exception was the direct cause of the following exception:

Traceback (most recent call last):
  File "/home/airflow/.local/lib/python3.8/site-packages/airflow/providers/docker/operators/docker.py", line 342, in _run_image
    return self._run_image_with_mounts([*self.mounts, tmp_mount], add_tmp_variable=True)
  File "/home/airflow/.local/lib/python3.8/site-packages/airflow/providers/docker/operators/docker.py", line 369, in _run_image_with_mounts
    self.container = self.cli.create_container(
  File "/home/airflow/.local/lib/python3.8/site-packages/docker/api/container.py", line 431, in create_container
    return self.create_container_from_config(config, name, platform)
  File "/home/airflow/.local/lib/python3.8/site-packages/docker/api/container.py", line 448, in create_container_from_config
    return self._result(res, True)
  File "/home/airflow/.local/lib/python3.8/site-packages/docker/api/client.py", line 274, in _result
    self._raise_for_status(response)
  File "/home/airflow/.local/lib/python3.8/site-packages/docker/api/client.py", line 270, in _raise_for_status
    raise create_api_error_from_http_exception(e) from e
  File "/home/airflow/.local/lib/python3.8/site-packages/docker/errors.py", line 39, in create_api_error_from_http_exception
    raise cls(e, response=response, explanation=explanation) from e
docker.errors.APIError: 400 Client Error for http://docker-proxy:2375/v1.43/containers/create?name=airflow-cb-stage: Bad Request ("invalid mount config for type "bind": bind source path does not exist: /tmp/airflowtmpbj0sd0l6")

During handling of the above exception, another exception occurred:

Traceback (most recent call last):
  File "/home/airflow/.local/lib/python3.8/site-packages/airflow/providers/docker/operators/docker.py", line 479, in execute
    return self._run_image()
  File "/home/airflow/.local/lib/python3.8/site-packages/airflow/providers/docker/operators/docker.py", line 351, in _run_image
    return self._run_image_with_mounts(self.mounts, add_tmp_variable=False)
  File "/home/airflow/.local/lib/python3.8/site-packages/airflow/providers/docker/operators/docker.py", line 414, in _run_image_with_mounts
    raise DockerContainerFailedException(f"Docker container failed: {result!r}", logs=log_lines)
airflow.providers.docker.exceptions.DockerContainerFailedException: Docker container failed: {'StatusCode': 1}
[2023-11-12T15:18:09.388+0000] {taskinstance.py:1398} INFO - Marking task as FAILED. dag_id=docker_cb, task_id=train_task, execution_date=20231112T151806, start_date=20231112T151807, end_date=20231112T151809
[2023-11-12T15:18:09.399+0000] {standard_task_runner.py:104} ERROR - Failed to execute job 3 for task train_task (Docker container failed: {'StatusCode': 1}; 73)
[2023-11-12T15:18:09.432+0000] {local_task_job_runner.py:228} INFO - Task exited with return code 1
[2023-11-12T15:18:09.447+0000] {taskinstance.py:2776} INFO - 0 downstream tasks scheduled from follow-on schedule check
