[2023-10-11T07:43:55.901+0000] {taskinstance.py:1157} INFO - Dependencies all met for dep_context=non-requeueable deps ti=<TaskInstance: docker.train_task manual__2023-10-11T07:43:54.878678+00:00 [queued]>
[2023-10-11T07:43:55.906+0000] {taskinstance.py:1157} INFO - Dependencies all met for dep_context=requeueable deps ti=<TaskInstance: docker.train_task manual__2023-10-11T07:43:54.878678+00:00 [queued]>
[2023-10-11T07:43:55.906+0000] {taskinstance.py:1359} INFO - Starting attempt 1 of 1
[2023-10-11T07:43:55.912+0000] {taskinstance.py:1380} INFO - Executing <Task(DockerOperator): train_task> on 2023-10-11 07:43:54.878678+00:00
[2023-10-11T07:43:55.917+0000] {standard_task_runner.py:57} INFO - Started process 539 to run task
[2023-10-11T07:43:55.920+0000] {standard_task_runner.py:84} INFO - Running: ['***', 'tasks', 'run', 'docker', 'train_task', 'manual__2023-10-11T07:43:54.878678+00:00', '--job-id', '1449', '--raw', '--subdir', 'DAGS_FOLDER/lightgbm/docker.py', '--cfg-path', '/tmp/tmp7dhpg7ww']
[2023-10-11T07:43:55.920+0000] {standard_task_runner.py:85} INFO - Job 1449: Subtask train_task
[2023-10-11T07:43:55.945+0000] {task_command.py:415} INFO - Running <TaskInstance: docker.train_task manual__2023-10-11T07:43:54.878678+00:00 [running]> on host 088fd7a9bc48
[2023-10-11T07:43:55.989+0000] {taskinstance.py:1660} INFO - Exporting env vars: AIRFLOW_CTX_DAG_OWNER='***' AIRFLOW_CTX_DAG_ID='docker' AIRFLOW_CTX_TASK_ID='train_task' AIRFLOW_CTX_EXECUTION_DATE='2023-10-11T07:43:54.878678+00:00' AIRFLOW_CTX_TRY_NUMBER='1' AIRFLOW_CTX_DAG_RUN_ID='manual__2023-10-11T07:43:54.878678+00:00'
[2023-10-11T07:43:56.017+0000] {docker.py:337} INFO - Starting docker container from image fullstackdatascience/***-lgb-stage:0.0.1
[2023-10-11T07:43:56.018+0000] {taskinstance.py:1935} ERROR - Task failed with exception
Traceback (most recent call last):
  File "/home/airflow/.local/lib/python3.8/site-packages/airflow/providers/docker/operators/docker.py", line 479, in execute
    return self._run_image()
  File "/home/airflow/.local/lib/python3.8/site-packages/airflow/providers/docker/operators/docker.py", line 342, in _run_image
    return self._run_image_with_mounts([*self.mounts, tmp_mount], add_tmp_variable=True)
  File "/home/airflow/.local/lib/python3.8/site-packages/airflow/providers/docker/operators/docker.py", line 369, in _run_image_with_mounts
    self.container = self.cli.create_container(
  File "/home/airflow/.local/lib/python3.8/site-packages/docker/api/container.py", line 431, in create_container
    return self.create_container_from_config(config, name, platform)
  File "/home/airflow/.local/lib/python3.8/site-packages/docker/api/container.py", line 447, in create_container_from_config
    res = self._post_json(u, data=config, params=params)
  File "/home/airflow/.local/lib/python3.8/site-packages/docker/api/client.py", line 296, in _post_json
    return self._post(url, data=json.dumps(data2), **kwargs)
  File "/usr/local/lib/python3.8/json/__init__.py", line 231, in dumps
    return _default_encoder.encode(obj)
  File "/usr/local/lib/python3.8/json/encoder.py", line 199, in encode
    chunks = self.iterencode(o, _one_shot=True)
  File "/usr/local/lib/python3.8/json/encoder.py", line 257, in iterencode
    return _iterencode(o, 0)
  File "/usr/local/lib/python3.8/json/encoder.py", line 179, in default
    raise TypeError(f'Object of type {o.__class__.__name__} '
TypeError: Object of type PosixPath is not JSON serializable
[2023-10-11T07:43:56.024+0000] {taskinstance.py:1398} INFO - Marking task as FAILED. dag_id=docker, task_id=train_task, execution_date=20231011T074354, start_date=20231011T074355, end_date=20231011T074356
[2023-10-11T07:43:56.030+0000] {standard_task_runner.py:104} ERROR - Failed to execute job 1449 for task train_task (Object of type PosixPath is not JSON serializable; 539)
[2023-10-11T07:43:56.051+0000] {local_task_job_runner.py:228} INFO - Task exited with return code 1
[2023-10-11T07:43:56.064+0000] {taskinstance.py:2776} INFO - 0 downstream tasks scheduled from follow-on schedule check
