[2023-10-11T04:37:22.099+0000] {taskinstance.py:1157} INFO - Dependencies all met for dep_context=non-requeueable deps ti=<TaskInstance: docker.virtualenv_python manual__2023-10-11T04:37:20.668475+00:00 [queued]>
[2023-10-11T04:37:22.103+0000] {taskinstance.py:1157} INFO - Dependencies all met for dep_context=requeueable deps ti=<TaskInstance: docker.virtualenv_python manual__2023-10-11T04:37:20.668475+00:00 [queued]>
[2023-10-11T04:37:22.103+0000] {taskinstance.py:1359} INFO - Starting attempt 1 of 1
[2023-10-11T04:37:22.109+0000] {taskinstance.py:1380} INFO - Executing <Task(_PythonVirtualenvDecoratedOperator): virtualenv_python> on 2023-10-11 04:37:20.668475+00:00
[2023-10-11T04:37:22.114+0000] {standard_task_runner.py:57} INFO - Started process 290 to run task
[2023-10-11T04:37:22.116+0000] {standard_task_runner.py:84} INFO - Running: ['***', 'tasks', 'run', 'docker', 'virtualenv_python', 'manual__2023-10-11T04:37:20.668475+00:00', '--job-id', '1406', '--raw', '--subdir', 'DAGS_FOLDER/docker.py', '--cfg-path', '/tmp/tmp5uv17gmr']
[2023-10-11T04:37:22.117+0000] {standard_task_runner.py:85} INFO - Job 1406: Subtask virtualenv_python
[2023-10-11T04:37:22.142+0000] {task_command.py:415} INFO - Running <TaskInstance: docker.virtualenv_python manual__2023-10-11T04:37:20.668475+00:00 [running]> on host 1e16ce4c9e98
[2023-10-11T04:37:22.179+0000] {taskinstance.py:1660} INFO - Exporting env vars: AIRFLOW_CTX_DAG_OWNER='***' AIRFLOW_CTX_DAG_ID='docker' AIRFLOW_CTX_TASK_ID='virtualenv_python' AIRFLOW_CTX_EXECUTION_DATE='2023-10-11T04:37:20.668475+00:00' AIRFLOW_CTX_TRY_NUMBER='1' AIRFLOW_CTX_DAG_RUN_ID='manual__2023-10-11T04:37:20.668475+00:00'
[2023-10-11T04:37:22.180+0000] {process_utils.py:182} INFO - Executing cmd: /usr/local/bin/python -m virtualenv /tmp/venvzcqtte9p
[2023-10-11T04:37:22.189+0000] {process_utils.py:186} INFO - Output:
[2023-10-11T04:37:23.063+0000] {process_utils.py:190} INFO - created virtual environment CPython3.8.18.final.0-64 in 308ms
[2023-10-11T04:37:23.063+0000] {process_utils.py:190} INFO -   creator CPython3Posix(dest=/tmp/venvzcqtte9p, clear=False, no_vcs_ignore=False, global=False)
[2023-10-11T04:37:23.063+0000] {process_utils.py:190} INFO -   seeder FromAppData(download=False, pip=bundle, setuptools=bundle, wheel=bundle, via=copy, app_data_dir=/tmp/tmpl6ukg5xm)
[2023-10-11T04:37:23.063+0000] {process_utils.py:190} INFO -     added seed packages: pip==23.2, setuptools==68.0.0, wheel==0.40.0
[2023-10-11T04:37:23.064+0000] {process_utils.py:190} INFO -   activators BashActivator,CShellActivator,FishActivator,NushellActivator,PowerShellActivator,PythonActivator
[2023-10-11T04:37:23.086+0000] {process_utils.py:182} INFO - Executing cmd: /tmp/venvzcqtte9p/bin/pip install -r /tmp/venvzcqtte9p/requirements.txt
[2023-10-11T04:37:23.096+0000] {process_utils.py:186} INFO - Output:
[2023-10-11T04:37:23.890+0000] {process_utils.py:190} INFO - WARNING: The directory '/home/***/.cache/pip' or its parent directory is not owned or is not writable by the current user. The cache has been disabled. Check the permissions and owner of that directory. If executing pip with sudo, you should use sudo's -H flag.
[2023-10-11T04:37:24.116+0000] {process_utils.py:190} INFO - Collecting lightgbm==4.1.0 (from -r /tmp/venvzcqtte9p/requirements.txt (line 1))
[2023-10-11T04:37:24.117+0000] {process_utils.py:190} INFO -   Obtaining dependency information for lightgbm==4.1.0 from https://files.pythonhosted.org/packages/b8/9d/1ce80cee7c5ef60f2fcc7e9fa97f29f7a8de3dc5a08922b3b2f1e9106481/lightgbm-4.1.0-py3-none-manylinux_2_28_x86_64.whl.metadata
[2023-10-11T04:37:24.259+0000] {process_utils.py:190} INFO -   Downloading lightgbm-4.1.0-py3-none-manylinux_2_28_x86_64.whl.metadata (19 kB)
[2023-10-11T04:37:24.636+0000] {process_utils.py:190} INFO - Collecting numpy (from lightgbm==4.1.0->-r /tmp/venvzcqtte9p/requirements.txt (line 1))
[2023-10-11T04:37:24.637+0000] {process_utils.py:190} INFO -   Obtaining dependency information for numpy from https://files.pythonhosted.org/packages/98/5d/5738903efe0ecb73e51eb44feafba32bdba2081263d40c5043568ff60faf/numpy-1.24.4-cp38-cp38-manylinux_2_17_x86_64.manylinux2014_x86_64.whl.metadata
[2023-10-11T04:37:24.689+0000] {process_utils.py:190} INFO -   Downloading numpy-1.24.4-cp38-cp38-manylinux_2_17_x86_64.manylinux2014_x86_64.whl.metadata (5.6 kB)
[2023-10-11T04:37:24.865+0000] {process_utils.py:190} INFO - Collecting scipy (from lightgbm==4.1.0->-r /tmp/venvzcqtte9p/requirements.txt (line 1))
[2023-10-11T04:37:24.904+0000] {process_utils.py:190} INFO -   Downloading scipy-1.10.1-cp38-cp38-manylinux_2_17_x86_64.manylinux2014_x86_64.whl (34.5 MB)
[2023-10-11T04:37:27.934+0000] {process_utils.py:190} INFO -      ━━━━━━━━━━━━━━━━━━━━━━━━━━━━━━━━━━━━━━━━ 34.5/34.5 MB 11.8 MB/s eta 0:00:00
[2023-10-11T04:37:28.027+0000] {process_utils.py:190} INFO - Downloading lightgbm-4.1.0-py3-none-manylinux_2_28_x86_64.whl (3.1 MB)
[2023-10-11T04:37:28.284+0000] {process_utils.py:190} INFO -    ━━━━━━━━━━━━━━━━━━━━━━━━━━━━━━━━━━━━━━━━ 3.1/3.1 MB 12.1 MB/s eta 0:00:00
[2023-10-11T04:37:28.321+0000] {process_utils.py:190} INFO - Downloading numpy-1.24.4-cp38-cp38-manylinux_2_17_x86_64.manylinux2014_x86_64.whl (17.3 MB)
[2023-10-11T04:37:29.798+0000] {process_utils.py:190} INFO -    ━━━━━━━━━━━━━━━━━━━━━━━━━━━━━━━━━━━━━━━━ 17.3/17.3 MB 11.8 MB/s eta 0:00:00
[2023-10-11T04:37:29.879+0000] {process_utils.py:190} INFO - Installing collected packages: numpy, scipy, lightgbm
[2023-10-11T04:37:33.081+0000] {process_utils.py:190} INFO - Successfully installed lightgbm-4.1.0 numpy-1.24.4 scipy-1.10.1
[2023-10-11T04:37:33.252+0000] {process_utils.py:190} INFO - 
[2023-10-11T04:37:33.253+0000] {process_utils.py:190} INFO - [notice] A new release of pip is available: 23.2 -> 23.2.1
[2023-10-11T04:37:33.253+0000] {process_utils.py:190} INFO - [notice] To update, run: python -m pip install --upgrade pip
[2023-10-11T04:37:33.320+0000] {process_utils.py:182} INFO - Executing cmd: /tmp/venvzcqtte9p/bin/python /tmp/venvzcqtte9p/script.py /tmp/venvzcqtte9p/script.in /tmp/venvzcqtte9p/script.out /tmp/venvzcqtte9p/string_args.txt /tmp/venvzcqtte9p/termination.log
[2023-10-11T04:37:33.331+0000] {process_utils.py:186} INFO - Output:
[2023-10-11T04:37:33.384+0000] {process_utils.py:190} INFO - Traceback (most recent call last):
[2023-10-11T04:37:33.385+0000] {process_utils.py:190} INFO -   File "/tmp/venvzcqtte9p/script.py", line 79, in <module>
[2023-10-11T04:37:33.385+0000] {process_utils.py:190} INFO -     res = train_task(*arg_dict["args"], **arg_dict["kwargs"])
[2023-10-11T04:37:33.385+0000] {process_utils.py:190} INFO -   File "/tmp/venvzcqtte9p/script.py", line 26, in train_task
[2023-10-11T04:37:33.385+0000] {process_utils.py:190} INFO -     import pandas as pd
[2023-10-11T04:37:33.385+0000] {process_utils.py:190} INFO - ModuleNotFoundError: No module named 'pandas'
[2023-10-11T04:37:33.550+0000] {taskinstance.py:1935} ERROR - Task failed with exception
Traceback (most recent call last):
  File "/home/airflow/.local/lib/python3.8/site-packages/airflow/decorators/base.py", line 221, in execute
    return_value = super().execute(context)
  File "/home/airflow/.local/lib/python3.8/site-packages/airflow/operators/python.py", line 395, in execute
    return super().execute(context=serializable_context)
  File "/home/airflow/.local/lib/python3.8/site-packages/airflow/operators/python.py", line 192, in execute
    return_value = self.execute_callable()
  File "/home/airflow/.local/lib/python3.8/site-packages/airflow/operators/python.py", line 602, in execute_callable
    result = self._execute_python_callable_in_subprocess(python_path, tmp_path)
  File "/home/airflow/.local/lib/python3.8/site-packages/airflow/operators/python.py", line 463, in _execute_python_callable_in_subprocess
    raise AirflowException(error_msg) from None
airflow.exceptions.AirflowException: Process returned non-zero exit status 1.
No module named 'pandas'
[2023-10-11T04:37:33.552+0000] {taskinstance.py:1398} INFO - Marking task as FAILED. dag_id=docker, task_id=virtualenv_python, execution_date=20231011T043720, start_date=20231011T043722, end_date=20231011T043733
[2023-10-11T04:37:33.559+0000] {standard_task_runner.py:104} ERROR - Failed to execute job 1406 for task virtualenv_python (Process returned non-zero exit status 1.
No module named 'pandas'; 290)
[2023-10-11T04:37:33.595+0000] {local_task_job_runner.py:228} INFO - Task exited with return code 1
[2023-10-11T04:37:33.605+0000] {taskinstance.py:2776} INFO - 0 downstream tasks scheduled from follow-on schedule check
